[2024-06-29T23:18:06.769+0000] {local_task_job_runner.py:120} INFO - ::group::Pre task execution logs
[2024-06-29T23:18:06.779+0000] {taskinstance.py:2076} INFO - Dependencies all met for dep_context=non-requeueable deps ti=<TaskInstance: amazon_analytics_dag.tsk_is_file_in_s3_available manual__2024-06-29T23:17:54.608779+00:00 [queued]>
[2024-06-29T23:18:06.785+0000] {taskinstance.py:2076} INFO - Dependencies all met for dep_context=requeueable deps ti=<TaskInstance: amazon_analytics_dag.tsk_is_file_in_s3_available manual__2024-06-29T23:17:54.608779+00:00 [queued]>
[2024-06-29T23:18:06.785+0000] {taskinstance.py:2306} INFO - Starting attempt 1 of 3
[2024-06-29T23:18:06.803+0000] {taskinstance.py:2330} INFO - Executing <Task(S3KeySensor): tsk_is_file_in_s3_available> on 2024-06-29 23:17:54.608779+00:00
[2024-06-29T23:18:06.809+0000] {standard_task_runner.py:63} INFO - Started process 44253 to run task
[2024-06-29T23:18:06.812+0000] {standard_task_runner.py:90} INFO - Running: ['airflow', 'tasks', 'run', 'amazon_analytics_dag', 'tsk_is_file_in_s3_available', 'manual__2024-06-29T23:17:54.608779+00:00', '--job-id', '209', '--raw', '--subdir', 'DAGS_FOLDER/amazonanalytics.py', '--cfg-path', '/tmp/tmpntlmpni3']
[2024-06-29T23:18:06.814+0000] {standard_task_runner.py:91} INFO - Job 209: Subtask tsk_is_file_in_s3_available
[2024-06-29T23:18:06.856+0000] {task_command.py:426} INFO - Running <TaskInstance: amazon_analytics_dag.tsk_is_file_in_s3_available manual__2024-06-29T23:17:54.608779+00:00 [running]> on host ip-172-31-19-147.us-west-2.compute.internal
[2024-06-29T23:18:06.945+0000] {taskinstance.py:2648} INFO - Exporting env vars: AIRFLOW_CTX_DAG_EMAIL='myemail@domain.com' AIRFLOW_CTX_DAG_OWNER='airflow' AIRFLOW_CTX_DAG_ID='amazon_analytics_dag' AIRFLOW_CTX_TASK_ID='tsk_is_file_in_s3_available' AIRFLOW_CTX_EXECUTION_DATE='2024-06-29T23:17:54.608779+00:00' AIRFLOW_CTX_TRY_NUMBER='1' AIRFLOW_CTX_DAG_RUN_ID='manual__2024-06-29T23:17:54.608779+00:00'
[2024-06-29T23:18:06.945+0000] {taskinstance.py:430} INFO - ::endgroup::
[2024-06-29T23:18:06.959+0000] {baseoperator.py:400} WARNING - S3KeySensor.execute cannot be called outside TaskInstance!
[2024-06-29T23:18:06.959+0000] {s3.py:117} INFO - Poking for key : s3://cleaned-data-zone-csv-bucket5/response_data_29062024231757.csv
[2024-06-29T23:18:06.965+0000] {base.py:84} INFO - Using connection ID 'aws_s3_conn' for task execution.
[2024-06-29T23:18:06.966+0000] {connection_wrapper.py:384} INFO - AWS Connection (conn_id='aws_s3_conn', conn_type='aws') credentials retrieved from login and password.
[2024-06-29T23:18:12.619+0000] {s3.py:117} INFO - Poking for key : s3://cleaned-data-zone-csv-bucket5/response_data_29062024231757.csv
[2024-06-29T23:18:17.630+0000] {s3.py:117} INFO - Poking for key : s3://cleaned-data-zone-csv-bucket5/response_data_29062024231757.csv
[2024-06-29T23:18:22.643+0000] {s3.py:117} INFO - Poking for key : s3://cleaned-data-zone-csv-bucket5/response_data_29062024231757.csv
[2024-06-29T23:18:27.652+0000] {s3.py:117} INFO - Poking for key : s3://cleaned-data-zone-csv-bucket5/response_data_29062024231757.csv
[2024-06-29T23:18:32.664+0000] {s3.py:117} INFO - Poking for key : s3://cleaned-data-zone-csv-bucket5/response_data_29062024231757.csv
[2024-06-29T23:18:37.674+0000] {s3.py:117} INFO - Poking for key : s3://cleaned-data-zone-csv-bucket5/response_data_29062024231757.csv
[2024-06-29T23:18:42.685+0000] {s3.py:117} INFO - Poking for key : s3://cleaned-data-zone-csv-bucket5/response_data_29062024231757.csv
[2024-06-29T23:18:47.693+0000] {s3.py:117} INFO - Poking for key : s3://cleaned-data-zone-csv-bucket5/response_data_29062024231757.csv
[2024-06-29T23:18:52.701+0000] {s3.py:117} INFO - Poking for key : s3://cleaned-data-zone-csv-bucket5/response_data_29062024231757.csv
[2024-06-29T23:18:57.712+0000] {s3.py:117} INFO - Poking for key : s3://cleaned-data-zone-csv-bucket5/response_data_29062024231757.csv
[2024-06-29T23:19:02.723+0000] {s3.py:117} INFO - Poking for key : s3://cleaned-data-zone-csv-bucket5/response_data_29062024231757.csv
[2024-06-29T23:19:07.734+0000] {s3.py:117} INFO - Poking for key : s3://cleaned-data-zone-csv-bucket5/response_data_29062024231757.csv
[2024-06-29T23:19:07.744+0000] {taskinstance.py:441} INFO - ::group::Post task execution logs
[2024-06-29T23:19:07.745+0000] {taskinstance.py:2905} ERROR - Task failed with exception
Traceback (most recent call last):
  File "/home/ubuntu/deevar_venv/lib/python3.12/site-packages/airflow/models/taskinstance.py", line 465, in _execute_task
    result = _execute_callable(context=context, **execute_callable_kwargs)
             ^^^^^^^^^^^^^^^^^^^^^^^^^^^^^^^^^^^^^^^^^^^^^^^^^^^^^^^^^^^^^
  File "/home/ubuntu/deevar_venv/lib/python3.12/site-packages/airflow/models/taskinstance.py", line 432, in _execute_callable
    return execute_callable(context=context, **execute_callable_kwargs)
           ^^^^^^^^^^^^^^^^^^^^^^^^^^^^^^^^^^^^^^^^^^^^^^^^^^^^^^^^^^^^
  File "/home/ubuntu/deevar_venv/lib/python3.12/site-packages/airflow/models/baseoperator.py", line 401, in wrapper
    return func(self, *args, **kwargs)
           ^^^^^^^^^^^^^^^^^^^^^^^^^^^
  File "/home/ubuntu/deevar_venv/lib/python3.12/site-packages/airflow/providers/amazon/aws/sensors/s3.py", line 183, in execute
    super().execute(context)
  File "/home/ubuntu/deevar_venv/lib/python3.12/site-packages/airflow/models/baseoperator.py", line 401, in wrapper
    return func(self, *args, **kwargs)
           ^^^^^^^^^^^^^^^^^^^^^^^^^^^
  File "/home/ubuntu/deevar_venv/lib/python3.12/site-packages/airflow/sensors/base.py", line 281, in execute
    raise AirflowSensorTimeout(message)
airflow.exceptions.AirflowSensorTimeout: Sensor has timed out; run duration of 60.78530225600116 seconds exceeds the specified timeout of 60.0.
[2024-06-29T23:19:07.749+0000] {taskinstance.py:1206} INFO - Immediate failure requested. Marking task as FAILED. dag_id=amazon_analytics_dag, task_id=tsk_is_file_in_s3_available, run_id=manual__2024-06-29T23:17:54.608779+00:00, execution_date=20240629T231754, start_date=20240629T231806, end_date=20240629T231907
[2024-06-29T23:19:07.761+0000] {standard_task_runner.py:110} ERROR - Failed to execute job 209 for task tsk_is_file_in_s3_available (Sensor has timed out; run duration of 60.78530225600116 seconds exceeds the specified timeout of 60.0.; 44253)
[2024-06-29T23:19:07.780+0000] {local_task_job_runner.py:240} INFO - Task exited with return code 1
[2024-06-29T23:19:07.798+0000] {taskinstance.py:3503} INFO - 0 downstream tasks scheduled from follow-on schedule check
[2024-06-29T23:19:07.811+0000] {local_task_job_runner.py:222} INFO - ::endgroup::
