[2024-06-29T20:03:34.558+0000] {local_task_job_runner.py:120} INFO - ::group::Pre task execution logs
[2024-06-29T20:03:34.568+0000] {taskinstance.py:2076} INFO - Dependencies all met for dep_context=non-requeueable deps ti=<TaskInstance: amazon_analytics_dag.tsk_is_file_in_s3_available manual__2024-06-29T20:03:22.472837+00:00 [queued]>
[2024-06-29T20:03:34.575+0000] {taskinstance.py:2076} INFO - Dependencies all met for dep_context=requeueable deps ti=<TaskInstance: amazon_analytics_dag.tsk_is_file_in_s3_available manual__2024-06-29T20:03:22.472837+00:00 [queued]>
[2024-06-29T20:03:34.575+0000] {taskinstance.py:2306} INFO - Starting attempt 1 of 3
[2024-06-29T20:03:34.591+0000] {taskinstance.py:2330} INFO - Executing <Task(S3KeySensor): tsk_is_file_in_s3_available> on 2024-06-29 20:03:22.472837+00:00
[2024-06-29T20:03:34.597+0000] {standard_task_runner.py:63} INFO - Started process 43340 to run task
[2024-06-29T20:03:34.600+0000] {standard_task_runner.py:90} INFO - Running: ['airflow', 'tasks', 'run', 'amazon_analytics_dag', 'tsk_is_file_in_s3_available', 'manual__2024-06-29T20:03:22.472837+00:00', '--job-id', '160', '--raw', '--subdir', 'DAGS_FOLDER/amazonanalytics.py', '--cfg-path', '/tmp/tmpa6ee3bg0']
[2024-06-29T20:03:34.602+0000] {standard_task_runner.py:91} INFO - Job 160: Subtask tsk_is_file_in_s3_available
[2024-06-29T20:03:34.641+0000] {task_command.py:426} INFO - Running <TaskInstance: amazon_analytics_dag.tsk_is_file_in_s3_available manual__2024-06-29T20:03:22.472837+00:00 [running]> on host ip-172-31-19-147.us-west-2.compute.internal
[2024-06-29T20:03:34.722+0000] {taskinstance.py:2648} INFO - Exporting env vars: AIRFLOW_CTX_DAG_EMAIL='myemail@domain.com' AIRFLOW_CTX_DAG_OWNER='airflow' AIRFLOW_CTX_DAG_ID='amazon_analytics_dag' AIRFLOW_CTX_TASK_ID='tsk_is_file_in_s3_available' AIRFLOW_CTX_EXECUTION_DATE='2024-06-29T20:03:22.472837+00:00' AIRFLOW_CTX_TRY_NUMBER='1' AIRFLOW_CTX_DAG_RUN_ID='manual__2024-06-29T20:03:22.472837+00:00'
[2024-06-29T20:03:34.722+0000] {taskinstance.py:430} INFO - ::endgroup::
[2024-06-29T20:03:34.735+0000] {baseoperator.py:400} WARNING - S3KeySensor.execute cannot be called outside TaskInstance!
[2024-06-29T20:03:34.735+0000] {s3.py:117} INFO - Poking for key : s3://cleaned-data-zone-csv-bucket5/response_data_29062024200325.csv
[2024-06-29T20:03:34.741+0000] {base.py:84} INFO - Using connection ID 'aws_s3_conn' for task execution.
[2024-06-29T20:03:34.741+0000] {connection_wrapper.py:384} INFO - AWS Connection (conn_id='aws_s3_conn', conn_type='aws') credentials retrieved from login and password.
[2024-06-29T20:03:40.379+0000] {s3.py:117} INFO - Poking for key : s3://cleaned-data-zone-csv-bucket5/response_data_29062024200325.csv
[2024-06-29T20:03:45.389+0000] {s3.py:117} INFO - Poking for key : s3://cleaned-data-zone-csv-bucket5/response_data_29062024200325.csv
[2024-06-29T20:03:50.399+0000] {s3.py:117} INFO - Poking for key : s3://cleaned-data-zone-csv-bucket5/response_data_29062024200325.csv
[2024-06-29T20:03:55.410+0000] {s3.py:117} INFO - Poking for key : s3://cleaned-data-zone-csv-bucket5/response_data_29062024200325.csv
[2024-06-29T20:04:00.420+0000] {s3.py:117} INFO - Poking for key : s3://cleaned-data-zone-csv-bucket5/response_data_29062024200325.csv
[2024-06-29T20:04:05.430+0000] {s3.py:117} INFO - Poking for key : s3://cleaned-data-zone-csv-bucket5/response_data_29062024200325.csv
[2024-06-29T20:04:10.440+0000] {s3.py:117} INFO - Poking for key : s3://cleaned-data-zone-csv-bucket5/response_data_29062024200325.csv
[2024-06-29T20:04:15.451+0000] {s3.py:117} INFO - Poking for key : s3://cleaned-data-zone-csv-bucket5/response_data_29062024200325.csv
[2024-06-29T20:04:20.470+0000] {s3.py:117} INFO - Poking for key : s3://cleaned-data-zone-csv-bucket5/response_data_29062024200325.csv
[2024-06-29T20:04:25.479+0000] {s3.py:117} INFO - Poking for key : s3://cleaned-data-zone-csv-bucket5/response_data_29062024200325.csv
[2024-06-29T20:04:30.490+0000] {s3.py:117} INFO - Poking for key : s3://cleaned-data-zone-csv-bucket5/response_data_29062024200325.csv
[2024-06-29T20:04:35.502+0000] {s3.py:117} INFO - Poking for key : s3://cleaned-data-zone-csv-bucket5/response_data_29062024200325.csv
[2024-06-29T20:04:35.513+0000] {taskinstance.py:441} INFO - ::group::Post task execution logs
[2024-06-29T20:04:35.514+0000] {taskinstance.py:2905} ERROR - Task failed with exception
Traceback (most recent call last):
  File "/home/ubuntu/deevar_venv/lib/python3.12/site-packages/airflow/models/taskinstance.py", line 465, in _execute_task
    result = _execute_callable(context=context, **execute_callable_kwargs)
             ^^^^^^^^^^^^^^^^^^^^^^^^^^^^^^^^^^^^^^^^^^^^^^^^^^^^^^^^^^^^^
  File "/home/ubuntu/deevar_venv/lib/python3.12/site-packages/airflow/models/taskinstance.py", line 432, in _execute_callable
    return execute_callable(context=context, **execute_callable_kwargs)
           ^^^^^^^^^^^^^^^^^^^^^^^^^^^^^^^^^^^^^^^^^^^^^^^^^^^^^^^^^^^^
  File "/home/ubuntu/deevar_venv/lib/python3.12/site-packages/airflow/models/baseoperator.py", line 401, in wrapper
    return func(self, *args, **kwargs)
           ^^^^^^^^^^^^^^^^^^^^^^^^^^^
  File "/home/ubuntu/deevar_venv/lib/python3.12/site-packages/airflow/providers/amazon/aws/sensors/s3.py", line 183, in execute
    super().execute(context)
  File "/home/ubuntu/deevar_venv/lib/python3.12/site-packages/airflow/models/baseoperator.py", line 401, in wrapper
    return func(self, *args, **kwargs)
           ^^^^^^^^^^^^^^^^^^^^^^^^^^^
  File "/home/ubuntu/deevar_venv/lib/python3.12/site-packages/airflow/sensors/base.py", line 281, in execute
    raise AirflowSensorTimeout(message)
airflow.exceptions.AirflowSensorTimeout: Sensor has timed out; run duration of 60.77810364199104 seconds exceeds the specified timeout of 60.0.
[2024-06-29T20:04:35.518+0000] {taskinstance.py:1206} INFO - Immediate failure requested. Marking task as FAILED. dag_id=amazon_analytics_dag, task_id=tsk_is_file_in_s3_available, run_id=manual__2024-06-29T20:03:22.472837+00:00, execution_date=20240629T200322, start_date=20240629T200334, end_date=20240629T200435
[2024-06-29T20:04:35.530+0000] {standard_task_runner.py:110} ERROR - Failed to execute job 160 for task tsk_is_file_in_s3_available (Sensor has timed out; run duration of 60.77810364199104 seconds exceeds the specified timeout of 60.0.; 43340)
[2024-06-29T20:04:35.563+0000] {local_task_job_runner.py:240} INFO - Task exited with return code 1
[2024-06-29T20:04:35.581+0000] {taskinstance.py:3503} INFO - 0 downstream tasks scheduled from follow-on schedule check
[2024-06-29T20:04:35.589+0000] {local_task_job_runner.py:222} INFO - ::endgroup::
